Traceback (most recent call last):
  File "E:\MainHomePage\.M_HomePage\Lib\site-packages\jupyter_cache\executors\utils.py", line 58, in single_nb_execution
    executenb(
  File "E:\MainHomePage\.M_HomePage\Lib\site-packages\nbclient\client.py", line 1314, in execute
    return NotebookClient(nb=nb, resources=resources, km=km, **kwargs).execute()
           ^^^^^^^^^^^^^^^^^^^^^^^^^^^^^^^^^^^^^^^^^^^^^^^^^^^^^^^^^^^^^^^^^^^^^
  File "E:\MainHomePage\.M_HomePage\Lib\site-packages\jupyter_core\utils\__init__.py", line 165, in wrapped
    return loop.run_until_complete(inner)
           ^^^^^^^^^^^^^^^^^^^^^^^^^^^^^^
  File "C:\Users\Dr\AppData\Local\Programs\Python\Python312\Lib\asyncio\base_events.py", line 687, in run_until_complete
    return future.result()
           ^^^^^^^^^^^^^^^
  File "E:\MainHomePage\.M_HomePage\Lib\site-packages\nbclient\client.py", line 709, in async_execute
    await self.async_execute_cell(
  File "E:\MainHomePage\.M_HomePage\Lib\site-packages\nbclient\client.py", line 1062, in async_execute_cell
    await self._check_raise_for_error(cell, cell_index, exec_reply)
  File "E:\MainHomePage\.M_HomePage\Lib\site-packages\nbclient\client.py", line 918, in _check_raise_for_error
    raise CellExecutionError.from_cell_and_msg(cell, exec_reply_content)
nbclient.exceptions.CellExecutionError: An error occurred while executing the following cell:
------------------
import pydot
from tensorflow.keras.utils import plot_model

def check_graphviz():
    try:
        pydot.Dot.create(pydot.Dot())
        print("pydot and Graphviz are properly installed.")
    except Exception as e:
        print(f"An error occurred: {e}")

check_graphviz()
------------------


[1;31m---------------------------------------------------------------------------[0m
[1;31mModuleNotFoundError[0m                       Traceback (most recent call last)
Cell [1;32mIn[1], line 1[0m
[1;32m----> 1[0m [38;5;28;01mimport[39;00m [38;5;21;01mpydot[39;00m
[0;32m      2[0m [38;5;28;01mfrom[39;00m [38;5;21;01mtensorflow[39;00m[38;5;21;01m.[39;00m[38;5;21;01mkeras[39;00m[38;5;21;01m.[39;00m[38;5;21;01mutils[39;00m [38;5;28;01mimport[39;00m plot_model
[0;32m      4[0m [38;5;28;01mdef[39;00m [38;5;21mcheck_graphviz[39m():

[1;31mModuleNotFoundError[0m: No module named 'pydot'

